Workbook
Name k_2023: '46k'!$H$5
Name k_2023: BASE_EXPORTACION!$H$5
Name kilos_2023: '46k'!$H$5
Name kilos_2023: BASE_EXPORTACION!$H$5
Name kilos_2023: Verdes!$H$5
Name quintales_2023: '46k'!$C$5
Name quintales_2023: BASE_EXPORTACION!$C$5
Name quintales_2023: Verdes!$C$5
Name TC_2023: '46k'!$F$5
Name TC_2023: BASE_EXPORTACION!$F$5
Name TC_2023: Verdes!$F$5

Sheet BASE_EXPORTACION
B1: MIG | C1: 45307
B2: PRESUPUESTO OPERACIONES | F2: UTILIDAD | G2: =+K45 -> -0.88562187 | H2: =+I45 -> -5142256.9 | I2: =+J41 -> -39849109 | K2: COLOCAR LA CANTIDAD DE CONTENEDORES
F3: (tc_2023) | J3: CONTENEDORES DE 20' (10,000 KG) | M3: 1 | N3: 10000
C4: 100 | D4: Qtz x qq | E4: TOTAL | F4: TC | G4: US$ | H4: Total Kilos | I4: $ x Kg | J4: CONTENEDORES DE 40' (23,000 KG) | M4: 0 | N4: 0
B5: Cantidad | C5: 500 | D5: 90000 | E5: =+quintales_2023*D5 -> 45000000 | F5: 7.75 | G5: =+E5/TC_2023 -> 5806451.6 | H5: =(C5*(1-H6)*(100/2.20462)) -> 21999.256 | I5: =+G5/kilos_2023 -> 263.93854 | J5: TOTAL CONTENEDORES | M5: =+SUM(M3:M4) -> 1 | N5: =SUM(N3:N4) -> 10000 | Q5: Relación precios | S5: Relación precios | U5: 2da. Relación precios
G6: Merma -> | H6: 0.03 | Q6: vista 24/oct/23 | S6: año 2020 | U6: Vista 24/oct/23 | W6: Kg por caja | X6: Cajas Producto Terminado | Y6: Quality
B7: % de los KG | C7: Percentage | D7: Quality | E7: Calidades | F7: Ponderado | G7: Kilos | H7: Precio Vta. | I7: Precio de Venta | J7: Precio de Venta Qtz | K7: % S/VENTA | M7: qq | N7: Qtz x qq | Q7: Precio Vta. | S7: Precio Vta. | U7: Precio Vta.
B8: =+G8/k_2023 -> 0.15 | C8: =SUM(F8+F9+F10) -> 0.5 | D8: SGQ | E8: P1 | F8: 0.15 | G8: =+k_2023*F8 -> 3299.8884 | H8: 38 | I8: =+H8*G8 -> 125395.76 | J8: =+I8*TC_2023 -> 971817.14 | K8: =+J8/$J$21 -> 0.16521739 | L8: =+G8/40 -> 82.49721 | M8: =+G8*2.20462/100 -> 72.75 | N8: =+H8*46*TC_2023 -> 13547 | Q8: 21.5 | S8: 22.5 | U8: 16.65 | W8: 40 | X8: =+G8/W8 -> 82.49721 | Y8: P1
B9: =+G9/k_2023 -> 0.15 | E9: P2 | F9: 0.15 | G9: =+F9*k_2023 -> 3299.8884 | H9: =H8-2 -> 36 | I9: =+H9*G9 -> 118795.98 | J9: =+I9*TC_2023 -> 920668.87 | K9: =+J9/$J$21 -> 0.15652174 | L9: =+G9/40 -> 82.49721 | M9: =+G9*2.20462/100 -> 72.75 | N9: =+H9*46*TC_2023 -> 12834 | Q9: =+Q8-1 -> 20.5 | S9: =+S8-1.5 -> 21 | U9: =+U8-1.5 -> 15.15 | W9: 40 | X9: =+G9/W9 -> 82.49721 | Y9: P2
B10: =+G10/k_2023 -> 0.2 | E10: P3 | F10: 0.2 | G10: =+F10*k_2023 -> 4399.8512 | H10: =H9-2.5 -> 33.5 | I10: =+H10*G10 -> 147395.02 | J10: =+I10*TC_2023 -> 1142311.4 | K10: =+J10/$J$21 -> 0.1942029 | L10: =+G10/40 -> 109.99628 | M10: =+G10*2.20462/100 -> 97 | N10: =+H10*46*TC_2023 -> 11942.75 | Q10: =+Q8-3 -> 18.5 | S10: =+S8-3.5 -> 19 | U10: =+U8-3.5 -> 13.15 | W10: 40 | X10: =+G10/W10 -> 109.99628 | Y10: P3
B11: =+G11/k_2023 -> 0.5 | F11: =+C8 -> 0.5 | G11: =SUM(G8:G10) -> 10999.628 | H11: =IFERROR(I11/G11,0) -> 35.6 | I11: =SUM(I8:I10) -> 391586.76 | J11: =SUM(J8:J10) -> 3034797.4 | K11: =+J11/$J$21 -> 0.51594203 | M11: =SUM(M8:M10) -> 242.5 | N11: =IFERROR(J11/M11,0) -> 12514.628 | Q11: =IFERROR(R11/P11,0) -> 0 | S11: =IFERROR(T11/R11,0) -> 0 | U11: =IFERROR(V11/T11,0) -> 0
B12: =+G12/k_2023 -> 0.3 | C12: =F12+F13 -> 0.5 | D12: PGQ | E12: S1 +7mm | F12: 0.3 | G12: =+F12*k_2023 -> 6599.7768 | H12: =H10+2 -> 35.5 | I12: =+H12*G12 -> 234292.08 | J12: =+I12*TC_2023 -> 1815763.6 | K12: =+J12/$J$21 -> 0.30869565 | L12: =+G12/40 -> 164.99442 | M12: =+G12*2.20462/100 -> 145.5 | N12: =+H12*46*TC_2023 -> 12655.75 | Q12: =+Q8-2.5 -> 19 | S12: =+S8-2.5 -> 20 | U12: =+U8-2.5 -> 14.15 | W12: 40 | X12: =+G12/W12 -> 164.99442 | Y12: S1 +7mm
B13: =+G13/k_2023 -> 0.2 | E13: S2 5-6mm | F13: 0.2 | G13: =+F13*k_2023 -> 4399.8512 | H13: =H12-5.25 -> 30.25 | I13: =+H13*G13 -> 133095.5 | J13: =+I13*TC_2023 -> 1031490.1 | K13: =+J13/$J$21 -> 0.17536232 | L13: =+G13/40 -> 109.99628 | M13: =+G13*2.20462/100 -> 97 | N13: =+H13*46*TC_2023 -> 10784.125 | Q13: =+Q8-4.5 -> 17 | S13: =+S8-3.75 -> 18.75 | U13: =+U8-4.5 -> 12.15 | W13: 40 | X13: =+G13/W13 -> 109.99628 | Y13: S2 5-6mm
B14: =+G14/k_2023 -> 0.5 | D14: =+(I11+I14)/E14 -> 34.5 | E14: =+G11+G14 -> 21999.256 | F14: =+C12 -> 0.5 | G14: =SUM(G12:G13) -> 10999.628 | H14: =IFERROR(I14/G14,0) -> 33.4 | I14: =SUM(I12:I13) -> 367387.58 | J14: =SUM(J12:J13) -> 2847253.7 | K14: =+J14/$J$21 -> 0.48405797 | M14: =SUM(M12:M13) -> 242.5 | N14: =IFERROR(J14/M14,0) -> 11741.252 | Q14: =IFERROR(R14/P14,0) -> 0 | S14: =IFERROR(T14/R14,0) -> 0 | U14: =IFERROR(V14/T14,0) -> 0
B15: =+G15/k_2023 -> 0 | C15: 0.05 | D15: MYQ | E15: Y | F15: 0 | G15: =+F15*H5 -> 0 | H15: =H13-2.5 -> 27.75 | I15: =+H15*G15 -> 0 | J15: =+I15*TC_2023 -> 0 | K15: =+J15/$J$21 -> 0 | L15: =+G15/40 -> 0 | M15: =+G15*2.20462/100 -> 0 | N15: =+H15*46*TC_2023 -> 9892.875 | Q15: =+Q8-7.5 -> 14 | S15: =+S8-11.75 -> 10.75 | U15: =+U8-9 -> 7.65 | W15: 40 | X15: =+G15/W15 -> 0 | Y15: MYQ
B16: =+G16/k_2023 -> 0 | C16: 0.16 | D16: Y | E16: GOP | F16: 0 | G16: =+F16*H5 -> 0 | H16: =H15-1 -> 26.75 | I16: =+H16*G16 -> 0 | J16: =+I16*TC_2023 -> 0 | K16: =+J16/$J$21 -> 0 | L16: =+G16/40 -> 0 | M16: =+G16*2.20462/100 -> 0 | N16: =+H16*46*TC_2023 -> 9536.375 | Q16: =+Q8-6 -> 15.5 | S16: =+S8-6 -> 16.5 | U16: =+U8-6.75 -> 9.9 | W16: 40 | X16: =+G16/W16 -> 0 | Y16: Y
B17: =+G17/k_2023 -> 0 | C17: 0.1 | D17: GOP | E17: TH | F17: 0 | G17: =+F17*H5 -> 0 | H17: =H16-1.254 -> 25.496 | I17: =+H17*G17 -> 0 | J17: =+I17*TC_2023 -> 0 | K17: =+J17/$J$21 -> 0 | L17: =+G17/40 -> 0 | M17: =+G17*2.20462/100 -> 0 | N17: =+H17*46*TC_2023 -> 9089.324 | Q17: =+Q8-6 -> 15.5 | S17: =+S8-5.5 -> 17 | U17: =+U8-6.5 -> 10.15 | W17: 40 | X17: =+G17/W17 -> 0 | Y17: GOP
B18: =+G18/k_2023 -> 0 | C18: 0.03 | D18: Seeds / ORO | E18: MYQ | F18: 0 | G18: =+F18*H5 -> 0 | H18: =H17-3.5 -> 21.996 | I18: =+H18*G18 -> 0 | J18: =+I18*TC_2023 -> 0 | K18: =+J18/$J$21 -> 0 | L18: =+G18/40 -> 0 | M18: =+G18*2.20462/100 -> 0 | N18: =+H18*46*TC_2023 -> 7841.574 | Q18: =Q8-5.5 -> 16 | S18: =S8-5.5 -> 17 | U18: =U8-6.5 -> 10.15 | W18: 40 | X18: =+G18/W18 -> 0 | Y18: ORO
B19: =+G19/k_2023 -> 0 | C19: 0.14 | D19: TH | E19: ORO | F19: 0 | G19: =+F19*H5 -> 0 | H19: =H17+1 -> 26.496 | I19: =+H19*G19 -> 0 | J19: =+I19*TC_2023 -> 0 | K19: =+J19/$J$21 -> 0 | L19: =+G19/40 -> 0 | M19: =+G19*2.20462/100 -> 0 | N19: =+H19*46*TC_2023 -> 9445.824 | Q19: =+Q8-6.5 -> 15 | S19: =+S8-6.5 -> 16 | U19: =+U8-8 -> 8.65 | W19: 40 | X19: =+G19/W19 -> 0 | Y19: TH
B20: =+G20/k_2023 -> 0 | F20: =SUM(F15:F19) -> 0 | G20: =SUM(G15:G19) -> 0 | H20: =IFERROR(I20/G20,0) -> 0 | I20: =SUM(I15:I19) -> 0 | J20: =SUM(J15:J19) -> 0 | K20: =+J20/$J$21 -> 0 | M20: =SUM(M15:M19) -> 0 | N20: =IFERROR(J20/M20,0) -> 0 | Q20: =IFERROR(R20/P20,0) -> 0 | S20: =IFERROR(T20/R20,0) -> 0 | U20: =IFERROR(V20/T20,0) -> 0
B21: =+G21/k_2023 -> 1 | C21: =+SUM(C7:C19) -> 1.48 | D21: Total | E21: TOTAL VENTA | F21: =+F11+F14+F20 -> 1 | G21: =+G11+G14+G20 -> 21999.256 | H21: =IFERROR(I21/G21,0) -> 34.5 | I21: =+I11+I14+I20 -> 758974.34 | J21: =+I21*TC_2023 -> 5882051.1 | K21: =+J21/$J$21 -> 1 | M21: =+M11+M14+M20 -> 485 | N21: =IFERROR(J21/M21,0) -> 12127.94 | Q21: =IFERROR(R21/P21,0) -> 0 | S21: =IFERROR(T21/R21,0) -> 0 | U21: =IFERROR(V21/T21,0) -> 0
E23: VALOR DE COMPRA | G23: =+kilos_2023 -> 21999.256 | H23: =+I23/G23 -> 263.93854 | I23: =+J23/TC_2023 -> 5806451.6 | J23: =+E5 -> 45000000 | K23: =J23/J21 -> 7.6503926
E25: UTILIDAD MARGINAL | G25: =+kilos_2023 -> 21999.256 | H25: =+I25/G25 -> -229.43854 | I25: =+I21-I23 -> -5047477.3 | J25: =+J21-J23 -> -39117949 | K25: =I25/I23 -> -0.86928775
D27: ANEXO 1 | E27: GASTOS DE COMPRA | G27: =+kilos_2023 -> 21999.256 | H27: =+I27/G27 -> 0 | I27: =+Anexo1_Gtos_Compra!D11 -> 0 | J27: =+Anexo1_Gtos_Compra!C11 -> 0 | K27: =+J27/$J$21 -> 0 | L27: =+K27+K28 -> 0.0067340455
D28: ANEXO 2 | E28: MAQUILA | G28: =+kilos_2023 -> 21999.256 | H28: =+I28/G28 -> 0.23232457 | I28: =+Anexo2_maquila!D6 -> 5110.9677 | J28: =+Anexo2_maquila!C6 -> 39610 | K28: =+J28/$J$21 -> 0.0067340455 | R28: 720 | S28: =R28/R38 -> 0.072 | T28: =S28*100 -> 7.2
D29: ANEXO 3 | E29: GASTOS EXPO. FIJOS x contenedor 20' | G29: =+M3 -> 1 | H29: =+Anexo3_Cont_20!G19 -> 0.614353 | I29: =+Anexo3_Cont_20!D19*G29 -> 6143.53 | J29: =+Anexo3_Cont_20!C19*G29 -> 47612.357 | K29: =+J29/$J$21 -> 0.0080945161 | L29: =+K29+K30+K31+K32 -> 0.01086977 | R29: 1240 | S29: =R29/R38 -> 0.124 | T29: =S29*100 -> 12.4
D30: ANEXO 3 | E30: GASTOS EXPO. Variables x contenedor 20' | G30: =+N3 -> 10000 | H30: =+Anexo3_Cont_20!G32 -> 0.21063466 | I30: =+G30*H30 -> 2106.3466 | J30: =+I30*TC_2023 -> 16324.186 | K30: =+J30/$J$21 -> 0.002775254 | R30: 1280 | S30: =R30/R38 -> 0.128 | T30: =S30*100 -> 12.8
D31: ANEXO 4 | E31: GASTOS EXPO. FIJOS x contenedor 40' | G31: =+M4 -> 0 | H31: =+Anexo4_Cont_40!G16 -> 0 | I31: =+J31/TC_2023 -> 0 | J31: =+Anexo4_Cont_40!C16*G31 -> 0 | K31: =+J31/$J$21 -> 0 | R31: 800 | S31: =R31/R38 -> 0.08 | T31: =S31*100 -> 8
D32: ANEXO 4 | E32: GASTOS EXPO. Variables x contenedor 40' | G32: =+N4 -> 0 | H32: =+Anexo4_Cont_40!G29 -> 0 | I32: =+J32/TC_2023 -> 0 | J32: =+Anexo4_Cont_40!C29 -> 0 | K32: =+J32/$J$21 -> 0 | R32: 1200 | S32: =R32/R38 -> 0.12 | T32: =S32*100 -> 12
D33: ANEXO 5 | E33: COSTO VARIABLE AL VALOR FACTURA | G33: =+kilos_2023 -> 21999.256 | H33: =+I33/G33 -> 0.44832115 | I33: =+Anexo5_Gtos_variables!E12 -> 9862.7317 | J33: =+I33*7.8 -> 76929.308 | K33: =+J33/$J$21 -> 0.013078653 | L33: =+K33 -> 0.013078653 | R33: 680 | S33: =R33/R38 -> 0.068 | T33: =S33*100 -> 6.8
R34: 1600 | S34: =R34/R38 -> 0.16 | T34: =S34*100 -> 16
E35: TOTAL COSTOS | G35: =+kilos_2023 -> 21999.256 | H35: =+I35/G35 -> 1.0556528 | I35: =SUM(I27:I33) -> 23223.576 | J35: =SUM(J27:J33) -> 180475.85 | K35: =J35/J23 -> 0.0040105745 | R35: 1000 | S35: =R35/R38 -> 0.1 | T35: =S35*100 -> 10
T36: =S36*100 -> 0
E37: UTILIDAD EXPORTACION | G37: =+kilos_2023 -> 21999.256 | H37: =+I37/G37 -> -230.4942 | I37: =+I25-I35 -> -5070700.9 | J37: =+J25-J35 -> -39298425 | K37: =J37/J23 -> -0.87329833 | N37: NECESIDAD DE EFECTIVO S/MONTO COMPRA | R37: 1480 | S37: =R37/R38 -> 0.148 | T37: =S37*100 -> 14.8
N38: TASA DE INTERES ANUAL | O38: MESES RETORNO | R38: =SUM(R28:R37) -> 10000
E39: COSTO FINANCIERO | G39: =+kilos_2023 -> 21999.256 | H39: =+I39/G39 -> 3.229929 | I39: =+J39/TC_2023 -> 71056.036 | J39: =+O41 -> 550684.28 | K39: =J39/J23 -> 0.012237428 | N39: 0.0975 | O39: 1.5
N40: MONTO COMPRA+GTOS | O40: INTERESES
E41: UTILIDAD ANTES DE ADMIN | G41: =+kilos_2023 -> 21999.256 | H41: =+H37-H39 -> -233.72413 | I41: =+I37-I39 -> -5141756.9 | J41: =+J37-J39 -> -39849109 | K41: =J41/J23 -> -0.88553576 | N41: =+J23+J35+J43 -> 45184351 | O41: =+N41*N39/12*O39 -> 550684.28
E43: GASTOS FIJOS | G43: =+kilos_2023 -> 21999.256 | H43: =+I43/G43 -> 0.022728041 | I43: 500 | J43: =+I43*TC_2023 -> 3875 | K43: =J43/J23 -> 8.6111111e-05
E45: UTILIDAD NETA ANTES DE ISR | G45: =+kilos_2023 -> 21999.256 | H45: =+H41-H43 -> -233.74685 | I45: =+I41-I43 -> -5142256.9 | J45: =+J41-J43 -> -39852984 | K45: =J45/J23 -> -0.88562187 | M45: MEDICION DE RESULTADOS FINANCIEROS
...

Sheet 46k
B1: MIG | C1: 45307
B2: PRESUPUESTO OPERACIONES | F2: UTILIDAD | G2: =+K45 -> 0.30172473 | H2: =+I45 -> 72633.296 | I2: =+J41 -> 566289.91 | K2: COLOCAR LA CANTIDAD DE CONTENEDORES
F3: (tc_2023) | J3: CONTENEDORES DE 20' (10,000 KG) | M3: 1 | N3: 10000
C4: 100 | D4: Qtz x qq | E4: TOTAL | F4: TC | G4: US$ | H4: Total Kilos | I4: $ x Kg | J4: CONTENEDORES DE 40' (23,000 KG) | M4: 0 | N4: 0
B5: Cantidad | C5: 233 | D5: 8000 | E5: =+quintales_2023*D5 -> 1864000 | F5: 7.75 | G5: =+E5/TC_2023 -> 240516.13 | H5: =C5*D6*0.97 -> 10396.46 | I5: =+G5/kilos_2023 -> 23.134425 | J5: TOTAL CONTENEDORES | M5: =+SUM(M3:M4) -> 1 | N5: =SUM(N3:N4) -> 10000 | Q5: Relación precios | S5: Relación precios | U5: 2da. Relación precios
C6: 1 | D6: 46 | G6: Merma -> | H6: 0.03 | Q6: vista 24/oct/23 | S6: año 2020 | U6: Vista 24/oct/23 | W6: Kg por caja | X6: Cajas Producto Terminado | Y6: Quality
B7: % de los KG | C7: Percentage | D7: Quality | E7: Calidades | F7: Ponderado | G7: Kilos | H7: Precio Vta. | I7: Precio de Venta | J7: Precio de Venta Qtz | K7: % S/VENTA | M7: qq | N7: Qtz x qq | Q7: Precio Vta. | S7: Precio Vta. | U7: Precio Vta.
B8: =+G8/'46k'!k_2023 -> 0.2 | C8: =SUM(F8+F9+F10) -> 0.55 | D8: SGQ | E8: P1 | F8: 0.2 | G8: =k_2023*F8 -> 2079.292 | H8: 38.5 | I8: =+H8*G8 -> 80052.742 | J8: =+I8*TC_2023 -> 620408.75 | K8: =+J8/$J$21 -> 0.23538403 | L8: =+G8/40 -> 51.9823 | M8: =+G8*2.20462/100 -> 45.840487 | N8: =+H8*46*TC_2023 -> 13725.25 | Q8: 21.5 | S8: 22.5 | U8: 16.65 | W8: 40 | X8: =+G8/W8 -> 51.9823 | Y8: P1
B9: =+G9/'46k'!k_2023 -> 0.2 | E9: P2 | F9: 0.2 | G9: =k_2023*F9 -> 2079.292 | H9: =H8-2 -> 36.5 | I9: =+H9*G9 -> 75894.158 | J9: =+I9*TC_2023 -> 588179.72 | K9: =+J9/$J$21 -> 0.22315629 | L9: =+G9/40 -> 51.9823 | M9: =+G9*2.20462/100 -> 45.840487 | N9: =+H9*46*TC_2023 -> 13012.25 | Q9: =+Q8-1 -> 20.5 | S9: =+S8-1.5 -> 21 | U9: =+U8-1.5 -> 15.15 | W9: 40 | X9: =+G9/W9 -> 51.9823 | Y9: P2
B10: =+G10/'46k'!k_2023 -> 0.15 | E10: P3 | F10: 0.15 | G10: =k_2023*F10 -> 1559.469 | H10: =H9-2.5 -> 34 | I10: =+H10*G10 -> 53021.946 | J10: =+I10*TC_2023 -> 410920.08 | K10: =+J10/$J$21 -> 0.15590371 | L10: =+G10/40 -> 38.986725 | M10: =+G10*2.20462/100 -> 34.380365 | N10: =+H10*46*TC_2023 -> 12121 | Q10: =+Q8-3 -> 18.5 | S10: =+S8-3.5 -> 19 | U10: =+U8-3.5 -> 13.15 | W10: 40 | X10: =+G10/W10 -> 38.986725 | Y10: P3
B11: =+G11/'46k'!k_2023 -> 0.55 | F11: =+C8 -> 0.55 | G11: =SUM(G8:G10) -> 5718.053 | H11: =IFERROR(I11/G11,0) -> 36.545455 | I11: =SUM(I8:I10) -> 208968.85 | J11: =SUM(J8:J10) -> 1619508.6 | K11: =+J11/$J$21 -> 0.61444402 | M11: =SUM(M8:M10) -> 126.06134 | N11: =IFERROR(J11/M11,0) -> 12846.988 | Q11: =IFERROR(R11/P11,0) -> 0 | S11: =IFERROR(T11/R11,0) -> 0 | U11: =IFERROR(V11/T11,0) -> 0
B12: =+G12/'46k'!k_2023 -> 0.08 | C12: =F12+F13 -> 0.16 | D12: PGQ | E12: S1 +7mm | F12: 0.08 | G12: =k_2023*F12 -> 831.7168 | H12: =H10+2 -> 36 | I12: =+H12*G12 -> 29941.805 | J12: =+I12*TC_2023 -> 232048.99 | K12: =+J12/$J$21 -> 0.08803974 | L12: =+G12/40 -> 20.79292 | M12: =+G12*2.20462/100 -> 18.336195 | N12: =+H12*46*TC_2023 -> 12834 | Q12: =+Q8-2.5 -> 19 | S12: =+S8-2.5 -> 20 | U12: =+U8-2.5 -> 14.15 | W12: 40 | X12: =+G12/W12 -> 20.79292 | Y12: S1 +7mm
B13: =+G13/'46k'!k_2023 -> 0.08 | E13: S2 5-6mm | F13: 0.08 | G13: =k_2023*F13 -> 831.7168 | H13: =H12-5.25 -> 30.75 | I13: =+H13*G13 -> 25575.292 | J13: =+I13*TC_2023 -> 198208.51 | K13: =+J13/$J$21 -> 0.075200611 | L13: =+G13/40 -> 20.79292 | M13: =+G13*2.20462/100 -> 18.336195 | N13: =+H13*46*TC_2023 -> 10962.375 | Q13: =+Q8-4.5 -> 17 | S13: =+S8-3.75 -> 18.75 | U13: =+U8-4.5 -> 12.15 | W13: 40 | X13: =+G13/W13 -> 20.79292 | Y13: S2 5-6mm
B14: =+G14/'46k'!k_2023 -> 0.16 | D14: =+(I11+I14)/E14 -> 35.830986 | E14: =+G11+G14 -> 7381.4866 | F14: =+C12 -> 0.16 | G14: =SUM(G12:G13) -> 1663.4336 | H14: =IFERROR(I14/G14,0) -> 33.375 | I14: =SUM(I12:I13) -> 55517.096 | J14: =SUM(J12:J13) -> 430257.5 | K14: =+J14/$J$21 -> 0.16324035 | M14: =SUM(M12:M13) -> 36.67239 | N14: =IFERROR(J14/M14,0) -> 11732.464 | Q14: =IFERROR(R14/P14,0) -> 0 | S14: =IFERROR(T14/R14,0) -> 0 | U14: =IFERROR(V14/T14,0) -> 0
B15: =+G15/'46k'!k_2023 -> 0.03 | C15: 0.05 | D15: MYQ | E15: GOP | F15: 0.03 | G15: =k_2023*F15 -> 311.8938 | H15: =H8-11.25 -> 27.25 | I15: =+H15*G15 -> 8499.106 | J15: =+I15*TC_2023 -> 65868.072 | K15: =+J15/$J$21 -> 0.024990447 | L15: =+G15/40 -> 7.797345 | M15: =+G15*2.20462/100 -> 6.8760731 | N15: =+H15*46*TC_2023 -> 9714.625 | Q15: =+Q8-7.5 -> 14 | S15: =+S8-11.75 -> 10.75 | U15: =+U8-9 -> 7.65 | W15: 40 | X15: =+G15/W15 -> 7.797345 | Y15: MYQ
B16: =+G16/'46k'!k_2023 -> 0.08 | C16: 0.16 | D16: Y | E16: YELLOW (LG) | F16: 0.08 | G16: =k_2023*F16 -> 831.7168 | H16: =H8-10.25 -> 28.25 | I16: =+H16*G16 -> 23496 | J16: =+I16*TC_2023 -> 182094 | K16: =+J16/$J$21 -> 0.069086741 | L16: =+G16/40 -> 20.79292 | M16: =+G16*2.20462/100 -> 18.336195 | N16: =+H16*46*TC_2023 -> 10071.125 | Q16: =+Q8-6 -> 15.5 | S16: =+S8-6 -> 16.5 | U16: =+U8-6.75 -> 9.9 | W16: 40 | X16: =+G16/W16 -> 20.79292 | Y16: Y
B17: =+G17/'46k'!k_2023 -> 0.07 | C17: 0.1 | D17: GOP | E17: MYQ | F17: 0.07 | G17: =k_2023*F17 -> 727.7522 | H17: =H8-16 -> 22.5 | I17: =+H17*G17 -> 16374.425 | J17: =+I17*TC_2023 -> 126901.79 | K17: =+J17/$J$21 -> 0.048146733 | L17: =+G17/40 -> 18.193805 | M17: =+G17*2.20462/100 -> 16.044171 | N17: =+H17*46*TC_2023 -> 8021.25 | Q17: =+Q8-6 -> 15.5 | S17: =+S8-5.5 -> 17 | U17: =+U8-6.5 -> 10.15 | W17: 40 | X17: =+G17/W17 -> 18.193805 | Y17: GOP
B18: =+G18/'46k'!k_2023 -> 0.08 | C18: 0.03 | D18: Seeds / ORO | E18: TRIP | F18: 0.08 | G18: =k_2023*F18 -> 831.7168 | H18: =H8-12.5 -> 26 | I18: =+H18*G18 -> 21624.637 | J18: =+I18*TC_2023 -> 167590.94 | K18: =+J18/$J$21 -> 0.063584257 | L18: =+G18/40 -> 20.79292 | M18: =+G18*2.20462/100 -> 18.336195 | N18: =+H18*46*TC_2023 -> 9269 | Q18: =Q8-5.5 -> 16 | S18: =S8-5.5 -> 17 | U18: =U8-6.5 -> 10.15 | W18: 40 | X18: =+G18/W18 -> 20.79292 | Y18: ORO
B19: =+G19/'46k'!k_2023 -> 0.02 | C19: 0.14 | D19: TH | E19: ORO | F19: 0.02 | G19: =k_2023*F19 -> 207.9292 | H19: =H8-11.5 -> 27 | I19: =+H19*G19 -> 5614.0884 | J19: =+I19*TC_2023 -> 43509.185 | K19: =+J19/$J$21 -> 0.016507451 | L19: =+G19/40 -> 5.19823 | M19: =+G19*2.20462/100 -> 4.5840487 | N19: =+H19*46*TC_2023 -> 9625.5 | Q19: =+Q8-6.5 -> 15 | S19: =+S8-6.5 -> 16 | U19: =+U8-8 -> 8.65 | W19: 40 | X19: =+G19/W19 -> 5.19823 | Y19: TH
B20: =+G20/'46k'!k_2023 -> 0.28 | F20: =SUM(F15:F19) -> 0.28 | G20: =SUM(G15:G19) -> 2911.0088 | H20: =IFERROR(I20/G20,0) -> 25.973214 | I20: =SUM(I15:I19) -> 75608.255 | J20: =SUM(J15:J19) -> 585963.98 | K20: =+J20/$J$21 -> 0.22231563 | M20: =SUM(M15:M19) -> 64.176682 | N20: =IFERROR(J20/M20,0) -> 9130.481 | Q20: =IFERROR(R20/P20,0) -> 0 | S20: =IFERROR(T20/R20,0) -> 0 | U20: =IFERROR(V20/T20,0) -> 0
B21: =+G21/'46k'!k_2023 -> 0.99 | C21: =+SUM(C7:C19) -> 1.19 | D21: Total | E21: TOTAL VENTA | F21: =+F11+F14+F20 -> 0.99 | G21: =+G11+G14+G20 -> 10292.495 | H21: =IFERROR(I21/G21,0) -> 33.042929 | I21: =+I11+I14+I20 -> 340094.2 | J21: =+I21*TC_2023 -> 2635730 | K21: =+J21/$J$21 -> 1 | M21: =+M11+M14+M20 -> 226.91041 | N21: =IFERROR(J21/M21,0) -> 11615.73 | Q21: =IFERROR(R21/P21,0) -> 0 | S21: =IFERROR(T21/R21,0) -> 0 | U21: =IFERROR(V21/T21,0) -> 0
E23: VALOR DE COMPRA | G23: =+kilos_2023 -> 10396.46 | H23: =+I23/G23 -> 23.134425 | I23: =+J23/TC_2023 -> 240516.13 | J23: =+E5 -> 1864000 | K23: =J23/J21 -> 0.70720445
E25: UTILIDAD MARGINAL | G25: =+kilos_2023 -> 10396.46 | H25: =+I25/G25 -> 9.5780745 | I25: =+I21-I23 -> 99578.069 | J25: =+J21-J23 -> 771730.03 | K25: =I25/I23 -> 0.41401826
D27: ANEXO 1 | E27: GASTOS DE COMPRA | G27: =+kilos_2023 -> 10396.46 | H27: =+I27/G27 -> 0 | I27: =+Anexo1_Gtos_Compra!D11 -> 0 | J27: =+Anexo1_Gtos_Compra!C11 -> 0 | K27: =+J27/$J$21 -> 0 | L27: =+K27+K28 -> 0.015028094
D28: ANEXO 2 | E28: MAQUILA | G28: =+kilos_2023 -> 10396.46 | H28: =+I28/G28 -> 0.49160654 | I28: =+Anexo2_maquila!D6 -> 5110.9677 | J28: =+Anexo2_maquila!C6 -> 39610 | K28: =+J28/$J$21 -> 0.015028094 | R28: 720 | S28: =R28/R38 -> 0.072 | T28: =S28*100 -> 7.2
D29: ANEXO 3 | E29: GASTOS EXPO. FIJOS x contenedor 20' | G29: =+M3 -> 1 | H29: =+Anexo3_Cont_20!G19 -> 0.614353 | I29: =+Anexo3_Cont_20!D19*G29 -> 6143.53 | J29: =+Anexo3_Cont_20!C19*G29 -> 47612.357 | K29: =+J29/$J$21 -> 0.018064201 | L29: =+K29+K30+K31+K32 -> 0.024257622 | R29: 1240 | S29: =R29/R38 -> 0.124 | T29: =S29*100 -> 12.4
D30: ANEXO 3 | E30: GASTOS EXPO. Variables x contenedor 20' | G30: =+N3 -> 10000 | H30: =+Anexo3_Cont_20!G32 -> 0.21063466 | I30: =+G30*H30 -> 2106.3466 | J30: =+I30*TC_2023 -> 16324.186 | K30: =+J30/$J$21 -> 0.006193421 | R30: 1280 | S30: =R30/R38 -> 0.128 | T30: =S30*100 -> 12.8
D31: ANEXO 4 | E31: GASTOS EXPO. FIJOS x contenedor 40' | G31: =+M4 -> 0 | H31: =+Anexo4_Cont_40!G16 -> 0 | I31: =+J31/TC_2023 -> 0 | J31: =+Anexo4_Cont_40!C16*G31 -> 0 | K31: =+J31/$J$21 -> 0 | R31: 800 | S31: =R31/R38 -> 0.08 | T31: =S31*100 -> 8
D32: ANEXO 4 | E32: GASTOS EXPO. Variables x contenedor 40' | G32: =+N4 -> 0 | H32: =+Anexo4_Cont_40!G29 -> 0 | I32: =+J32/TC_2023 -> 0 | J32: =+Anexo4_Cont_40!C29 -> 0 | K32: =+J32/$J$21 -> 0 | R32: 1200 | S32: =R32/R38 -> 0.12 | T32: =S32*100 -> 12
D33: ANEXO 5 | E33: COSTO VARIABLE AL VALOR FACTURA | G33: =+kilos_2023 -> 10396.46 | H33: =+I33/G33 -> 0.9486625 | I33: =+Anexo5_Gtos_variables!E12 -> 9862.7317 | J33: =+I33*7.8 -> 76929.308 | K33: =+J33/$J$21 -> 0.029187097 | L33: =+K33 -> 0.029187097 | R33: 680 | S33: =R33/R38 -> 0.068 | T33: =S33*100 -> 6.8
R34: 1600 | S34: =R34/R38 -> 0.16 | T34: =S34*100 -> 16
E35: TOTAL COSTOS | G35: =+kilos_2023 -> 10396.46 | H35: =+I35/G35 -> 2.2337965 | I35: =SUM(I27:I33) -> 23223.576 | J35: =SUM(J27:J33) -> 180475.85 | K35: =J35/J23 -> 0.096821808 | R35: 1000 | S35: =R35/R38 -> 0.1 | T35: =S35*100 -> 10
T36: =S36*100 -> 0
E37: UTILIDAD EXPORTACION | G37: =+kilos_2023 -> 10396.46 | H37: =+I37/G37 -> 7.344278 | I37: =+I25-I35 -> 76354.493 | J37: =+J25-J35 -> 591254.18 | K37: =J37/J23 -> 0.31719645 | N37: NECESIDAD DE EFECTIVO S/MONTO COMPRA | R37: 1480 | S37: =R37/R38 -> 0.148 | T37: =S37*100 -> 14.8
N38: TASA DE INTERES ANUAL | O38: MESES RETORNO | R38: =SUM(R28:R37) -> 10000
E39: COSTO FINANCIERO | G39: =+kilos_2023 -> 10396.46 | H39: =+I39/G39 -> 0.30983593 | I39: =+J39/TC_2023 -> 3221.1969 | J39: =+O41 -> 24964.276 | K39: =J39/J23 -> 0.013392852 | N39: 0.0975 | O39: 1.5
N40: MONTO COMPRA+GTOS | O40: INTERESES
E41: UTILIDAD ANTES DE ADMIN | G41: =+kilos_2023 -> 10396.46 | H41: =+H37-H39 -> 7.0344421 | I41: =+I37-I39 -> 73133.296 | J41: =+J37-J39 -> 566289.91 | K41: =J41/J23 -> 0.3038036 | N41: =+J23+J35+J43 -> 2048350.9 | O41: =+N41*N39/12*O39 -> 24964.276
E43: GASTOS FIJOS | G43: =+kilos_2023 -> 10396.46 | H43: =+I43/G43 -> 0.048093293 | I43: 500 | J43: =+I43*TC_2023 -> 3875 | K43: =J43/J23 -> 0.0020788627
E45: UTILIDAD NETA ANTES DE ISR | G45: =+kilos_2023 -> 10396.46 | H45: =+H41-H43 -> 6.9863488 | I45: =+I41-I43 -> 72633.296 | J45: =+J41-J43 -> 562414.91 | K45: =J45/J23 -> 0.30172473 | M45: MEDICION DE RESULTADOS FINANCIEROS
...

Sheet Verdes
B1: MIG | C1: 45307 | E1: TOTAL KILOS COMPRA | F1: =quintales_2023*46 -> 10718 | H1: Diferencia Merma | I1: =F1-kilos_2023 -> 321.54
B2: PRESUPUESTO OPERACIONES | F2: UTILIDAD | G2: =+K45 -> 0.3502903 | H2: =+I45 -> 84314.098 | I2: =+J41 -> 656816.12 | K2: COLOCAR LA CANTIDAD DE CONTENEDORES
F3: (tc_2023) | J3: CONTENEDORES DE 20' (10,000 KG) | M3: 1 | N3: 10000
C4: 100 | D4: Qtz x qq | E4: TOTAL | F4: TC | G4: US$ | H4: Total Kilos | I4: $ x Kg | J4: CONTENEDORES DE 40' (23,000 KG) | M4: 0 | N4: 0
B5: Cantidad | C5: 233 | D5: 8000 | E5: =+quintales_2023*D5 -> 1864000 | F5: 7.75 | G5: =+E5/TC_2023 -> 240516.13 | H5: =C5*D6*0.97 -> 10396.46 | I5: =+G5/kilos_2023 -> 23.134425 | J5: TOTAL CONTENEDORES | M5: =+SUM(M3:M4) -> 1 | N5: =SUM(N3:N4) -> 10000 | Q5: Relación precios | S5: Relación precios | U5: 2da. Relación precios
C6: 1 | D6: 46 | G6: Merma -> | H6: 0.03 | Q6: vista 24/oct/23 | S6: año 2020 | U6: Vista 24/oct/23 | W6: Kg por caja | X6: Cajas Producto Terminado | Y6: Quality
B7: % de los KG | C7: Percentage | D7: Quality | E7: Calidades | F7: Kilos | G7: Precio Vta. | H7: Precio de Venta | I7: Precio de Venta Qtz | J7: % S/VENTA | L7: qq | M7: Qtz x qq | P7: Precio Vta. | R7: Precio Vta. | T7: Precio Vta.
B8: =+F8/'46k'!k_2023 -> 0.25008513 | C8: =SUM(#REF!+#REF!+#REF!) -> #REF! | D8: SGQ | E8: P1 | F8: 2600 | G8: 33 | H8: =+G8*F8 -> 85800 | I8: =+H8*TC_2023 -> 664950 | J8: =+I8/$I$21 -> 0.24390591 | K8: =+F8/40 -> 65 | L8: =+F8*2.20462/100 -> 57.32012 | M8: =+G8*46*TC_2023 -> 11764.5 | P8: 21.5 | R8: 22.5 | T8: 16.65 | V8: 40 | W8: =+F8/V8 -> 65 | X8: P1
B9: =+F9/'46k'!k_2023 -> 0.17313586 | E9: P2 | F9: 1800 | G9: 38.5 | H9: =+G9*F9 -> 69300 | I9: =+H9*TC_2023 -> 537075 | J9: =+I9/$I$21 -> 0.19700092 | K9: =+F9/40 -> 45 | L9: =+F9*2.20462/100 -> 39.68316 | M9: =+G9*46*TC_2023 -> 13725.25 | P9: =+P8-1 -> 20.5 | R9: =+R8-1.5 -> 21 | T9: =+T8-1.5 -> 15.15 | V9: 40 | W9: =+F9/V9 -> 45 | X9: P2
B10: =+F10/'46k'!k_2023 -> 0.15389854 | E10: P3 | F10: 1600 | G10: 36 | H10: =+G10*F10 -> 57600 | I10: =+H10*TC_2023 -> 446400 | J10: =+I10/$I$21 -> 0.16374103 | K10: =+F10/40 -> 40 | L10: =+F10*2.20462/100 -> 35.27392 | M10: =+G10*46*TC_2023 -> 12834 | P10: =+P8-3 -> 18.5 | R10: =+R8-3.5 -> 19 | T10: =+T8-3.5 -> 13.15 | V10: 40 | W10: =+F10/V10 -> 40 | X10: P3
B11: =+F11/'46k'!k_2023 -> 0.57711952 | F11: =SUM(F8:F10) -> 6000 | H11: =SUM(H8:H10) -> 212700 | I11: =SUM(I8:I10) -> 1648425 | J11: =+I11/$I$21 -> 0.60464786 | L11: =SUM(L8:L10) -> 132.2772 | M11: =IFERROR(I11/L11,0) -> 12461.898 | P11: =IFERROR(Q11/O11,0) -> 0 | R11: =IFERROR(S11/Q11,0) -> 0 | T11: =IFERROR(U11/S11,0) -> 0
B12: =+F12/'46k'!k_2023 -> 0.096186587 | C12: =#REF!+#REF! -> #REF! | D12: PGQ | E12: S1 +7mm | F12: 1000 | G12: 38 | H12: =+G12*F12 -> 38000 | I12: =+H12*TC_2023 -> 294500 | J12: =+I12/$I$21 -> 0.10802359 | K12: =+F12/40 -> 25 | L12: =+F12*2.20462/100 -> 22.0462 | M12: =+G12*46*TC_2023 -> 13547 | P12: =+P8-2.5 -> 19 | R12: =+R8-2.5 -> 20 | T12: =+T8-2.5 -> 14.15 | V12: 40 | W12: =+F12/V12 -> 25 | X12: S1 +7mm
B13: =+F13/'46k'!k_2023 -> 0.096186587 | E13: S2 5-6mm | F13: 1000 | G13: 32.75 | H13: =+G13*F13 -> 32750 | I13: =+H13*TC_2023 -> 253812.5 | J13: =+I13/$I$21 -> 0.093099282 | K13: =+F13/40 -> 25 | L13: =+F13*2.20462/100 -> 22.0462 | M13: =+G13*46*TC_2023 -> 11675.375 | P13: =+P8-4.5 -> 17 | R13: =+R8-3.75 -> 18.75 | T13: =+T8-4.5 -> 12.15 | V13: 40 | W13: =+F13/V13 -> 25 | X13: S2 5-6mm
B14: =+F14/'46k'!k_2023 -> 0.19237317 | D14: =+(H11+H14)/E14 -> 35.43125 | E14: =+F11+F14 -> 8000 | F14: =F12+F13 -> 2000 | H14: =SUM(H12:H13) -> 70750 | I14: =SUM(I12:I13) -> 548312.5 | J14: =+I14/$I$21 -> 0.20112288 | L14: =SUM(L12:L13) -> 44.0924 | M14: =IFERROR(I14/L14,0) -> 12435.533 | P14: =IFERROR(Q14/O14,0) -> 0 | R14: =IFERROR(S14/Q14,0) -> 0 | T14: =IFERROR(U14/S14,0) -> 0
B15: =+F15/'46k'!k_2023 -> 0.086567928 | C15: 0.05 | D15: MYQ | E15: GOP | F15: 900 | G15: 29.25 | H15: =+G15*F15 -> 26325 | I15: =+H15*TC_2023 -> 204018.75 | J15: =+I15/$I$21 -> 0.074834767 | K15: =+F15/40 -> 22.5 | L15: =+F15*2.20462/100 -> 19.84158 | M15: =+G15*46*TC_2023 -> 10427.625 | P15: =+P8-7.5 -> 14 | R15: =+R8-11.75 -> 10.75 | T15: =+T8-9 -> 7.65 | V15: 40 | W15: =+F15/V15 -> 22.5 | X15: MYQ
B16: =+F16/'46k'!k_2023 -> 0 | C16: 0.16 | D16: Y | E16: YELLOW (LG) | G16: 29.25 | H16: =+G16*F16 -> 0 | I16: =+H16*TC_2023 -> 0 | J16: =+I16/$I$21 -> 0 | K16: =+F16/40 -> 0 | L16: =+F16*2.20462/100 -> 0 | M16: =+G16*46*TC_2023 -> 10427.625 | P16: =+P8-6 -> 15.5 | R16: =+R8-6 -> 16.5 | T16: =+T8-6.75 -> 9.9 | V16: 40 | W16: =+F16/V16 -> 0 | X16: Y
B17: =+F17/'46k'!k_2023 -> 0 | C17: 0.1 | D17: GOP | E17: MYQ | G17: 24.5 | H17: =+G17*F17 -> 0 | I17: =+H17*TC_2023 -> 0 | J17: =+I17/$I$21 -> 0 | K17: =+F17/40 -> 0 | L17: =+F17*2.20462/100 -> 0 | M17: =+G17*46*TC_2023 -> 8734.25 | P17: =+P8-6 -> 15.5 | R17: =+R8-5.5 -> 17 | T17: =+T8-6.5 -> 10.15 | V17: 40 | W17: =+F17/V17 -> 0 | X17: GOP
B18: =+F18/'46k'!k_2023 -> 0.14427988 | C18: 0.03 | D18: Seeds / ORO | E18: TRIP | F18: 1500 | G18: 28 | H18: =+G18*F18 -> 42000 | I18: =+H18*TC_2023 -> 325500 | J18: =+I18/$I$21 -> 0.1193945 | K18: =+F18/40 -> 37.5 | L18: =+F18*2.20462/100 -> 33.0693 | M18: =+G18*46*TC_2023 -> 9982 | P18: =P8-5.5 -> 16 | R18: =R8-5.5 -> 17 | T18: =T8-6.5 -> 10.15 | V18: 40 | W18: =+F18/V18 -> 37.5 | X18: ORO
B19: =+F19/'46k'!k_2023 -> 0 | C19: 0.14 | D19: TH | E19: ORO | G19: 29 | H19: =+G19*F19 -> 0 | I19: =+H19*TC_2023 -> 0 | J19: =+I19/$I$21 -> 0 | K19: =+F19/40 -> 0 | L19: =+F19*2.20462/100 -> 0 | M19: =+G19*46*TC_2023 -> 10338.5 | P19: =+P8-6.5 -> 15 | R19: =+R8-6.5 -> 16 | T19: =+T8-8 -> 8.65 | V19: 40 | W19: =+F19/V19 -> 0 | X19: TH
B20: =+F20/'46k'!k_2023 -> 0.23084781 | F20: =F15+F16+F17+F18+F19 -> 2400 | G20: =IFERROR(H20/F20,0) -> 28.46875 | H20: =SUM(H15:H19) -> 68325 | I20: =SUM(I15:I19) -> 529518.75 | J20: =+I20/$I$21 -> 0.19422927 | L20: =SUM(L15:L19) -> 52.91088 | M20: =IFERROR(I20/L20,0) -> 10007.748 | P20: =IFERROR(Q20/O20,0) -> 0 | R20: =IFERROR(S20/Q20,0) -> 0 | T20: =IFERROR(U20/S20,0) -> 0
B21: =+F21/'46k'!k_2023 -> 1.0003405 | C21: =+SUM(C7:C19) -> #REF! | D21: Total | E21: TOTAL VENTA | F21: =F11+F14+F20 -> 10400 | G21: =IFERROR(H21/F21,0) -> 33.824519 | H21: =+H11+H14+H20 -> 351775 | I21: =+H21*TC_2023 -> 2726256.2 | J21: =+I21/$I$21 -> 1 | L21: =+L11+L14+L20 -> 229.28048 | M21: =IFERROR(I21/L21,0) -> 11890.486 | P21: =IFERROR(Q21/O21,0) -> 0 | R21: =IFERROR(S21/Q21,0) -> 0 | T21: =IFERROR(U21/S21,0) -> 0
E23: VALOR DE COMPRA | G23: =+kilos_2023 -> 10396.46 | H23: =+I23/G23 -> 23.134425 | I23: =+J23/TC_2023 -> 240516.13 | J23: =+E5 -> 1864000 | K23: =J23/I21 -> 0.6837215
E25: UTILIDAD MARGINAL | G25: =+kilos_2023 -> 10396.46 | H25: =+I25/G25 -> 10.701611 | I25: =+H21-I23 -> 111258.87 | J25: =+I21-J23 -> 862256.25 | K25: =I25/I23 -> 0.46258383
D27: ANEXO 1 | E27: GASTOS DE COMPRA | G27: =+kilos_2023 -> 10396.46 | H27: =+I27/G27 -> 0 | I27: =+Anexo1_Gtos_Compra!D11 -> 0 | J27: =+Anexo1_Gtos_Compra!C11 -> 0 | K27: =+J27/$I$21 -> 0 | L27: =+K27+K28 -> 0.014529082
D28: ANEXO 2 | E28: MAQUILA | G28: =+kilos_2023 -> 10396.46 | H28: =+I28/G28 -> 0.49160654 | I28: =+Anexo2_maquila!D6 -> 5110.9677 | J28: =+Anexo2_maquila!C6 -> 39610 | K28: =+J28/$I$21 -> 0.014529082 | R28: 720 | S28: =R28/R38 -> 0.072 | T28: =S28*100 -> 7.2
D29: ANEXO 3 | E29: GASTOS EXPO. FIJOS x contenedor 20' | G29: =+M3 -> 1 | H29: =+Anexo3_Cont_20!G19 -> 0.614353 | I29: =+Anexo3_Cont_20!D19*G29 -> 6143.53 | J29: =+Anexo3_Cont_20!C19*G29 -> 47612.357 | K29: =+J29/$I$21 -> 0.017464374 | L29: =+K29+K30+K31+K32 -> 0.02345214 | R29: 1240 | S29: =R29/R38 -> 0.124 | T29: =S29*100 -> 12.4
D30: ANEXO 3 | E30: GASTOS EXPO. Variables x contenedor 20' | G30: =+N3 -> 10000 | H30: =+Anexo3_Cont_20!G32 -> 0.21063466 | I30: =+G30*H30 -> 2106.3466 | J30: =+I30*TC_2023 -> 16324.186 | K30: =+J30/$I$21 -> 0.0059877665 | R30: 1280 | S30: =R30/R38 -> 0.128 | T30: =S30*100 -> 12.8
D31: ANEXO 4 | E31: GASTOS EXPO. FIJOS x contenedor 40' | G31: =+M4 -> 0 | H31: =+Anexo4_Cont_40!G16 -> 0 | I31: =+J31/TC_2023 -> 0 | J31: =+Anexo4_Cont_40!C16*G31 -> 0 | K31: =+J31/$I$21 -> 0 | R31: 800 | S31: =R31/R38 -> 0.08 | T31: =S31*100 -> 8
D32: ANEXO 4 | E32: GASTOS EXPO. Variables x contenedor 40' | G32: =+N4 -> 0 | H32: =+Anexo4_Cont_40!G29 -> 0 | I32: =+J32/TC_2023 -> 0 | J32: =+Anexo4_Cont_40!C29 -> 0 | K32: =+J32/$I$21 -> 0 | R32: 1200 | S32: =R32/R38 -> 0.12 | T32: =S32*100 -> 12
D33: ANEXO 5 | E33: COSTO VARIABLE AL VALOR FACTURA | G33: =+kilos_2023 -> 10396.46 | H33: =+I33/G33 -> 0.9486625 | I33: =+Anexo5_Gtos_variables!E12 -> 9862.7317 | J33: =+I33*7.8 -> 76929.308 | K33: =+J33/$I$21 -> 0.02821793 | L33: =+K33 -> 0.02821793 | R33: 680 | S33: =R33/R38 -> 0.068 | T33: =S33*100 -> 6.8
R34: 1600 | S34: =R34/R38 -> 0.16 | T34: =S34*100 -> 16
E35: TOTAL COSTOS | G35: =+kilos_2023 -> 10396.46 | H35: =+I35/G35 -> 2.2337965 | I35: =SUM(I27:I33) -> 23223.576 | J35: =SUM(J27:J33) -> 180475.85 | K35: =J35/J23 -> 0.096821808 | R35: 1000 | S35: =R35/R38 -> 0.1 | T35: =S35*100 -> 10
T36: =S36*100 -> 0
E37: UTILIDAD EXPORTACION | G37: =+kilos_2023 -> 10396.46 | H37: =+I37/G37 -> 8.4678145 | I37: =+I25-I35 -> 88035.295 | J37: =+J25-J35 -> 681780.4 | K37: =J37/J23 -> 0.36576202 | N37: NECESIDAD DE EFECTIVO S/MONTO COMPRA | R37: 1480 | S37: =R37/R38 -> 0.148 | T37: =S37*100 -> 14.8
N38: TASA DE INTERES ANUAL | O38: MESES RETORNO | R38: =SUM(R28:R37) -> 10000
E39: COSTO FINANCIERO | G39: =+kilos_2023 -> 10396.46 | H39: =+I39/G39 -> 0.30983593 | I39: =+J39/TC_2023 -> 3221.1969 | J39: =+O41 -> 24964.276 | K39: =J39/J23 -> 0.013392852 | N39: 0.0975 | O39: 1.5
N40: MONTO COMPRA+GTOS | O40: INTERESES
E41: UTILIDAD ANTES DE ADMIN | G41: =+kilos_2023 -> 10396.46 | H41: =+H37-H39 -> 8.1579786 | I41: =+I37-I39 -> 84814.098 | J41: =+J37-J39 -> 656816.12 | K41: =J41/J23 -> 0.35236916 | N41: =+J23+J35+J43 -> 2048350.9 | O41: =+N41*N39/12*O39 -> 24964.276
E43: GASTOS FIJOS | G43: =+kilos_2023 -> 10396.46 | H43: =+I43/G43 -> 0.048093293 | I43: 500 | J43: =+I43*TC_2023 -> 3875 | K43: =J43/J23 -> 0.0020788627
E45: UTILIDAD NETA ANTES DE ISR | G45: =+kilos_2023 -> 10396.46 | H45: =+H41-H43 -> 8.1098853 | I45: =+I41-I43 -> 84314.098 | J45: =+J41-J43 -> 652941.12 | K45: =J45/J23 -> 0.3502903 | M45: MEDICION DE RESULTADOS FINANCIEROS
...

Sheet Anexo1_Gtos_Compra
B2: ANEXO 1
B3: GASTOS DE COMPRA | C3: Costo total Qtz | D3: Costo total $ | E3: qq | F3: Qtz x qq | G3: US$ x qq | H3: US$ x kg
B4: Flete Interno | C4: =F4*E4 -> 0 | D4: =+C4/BASE_EXPORTACION!TC_2023 -> 0 | E4: ='46k'!quintales_2023 -> 233 | F4: 0 | G4: =+F4/BASE_EXPORTACION!TC_2023 -> 0 | H4: =+G4/46 -> 0 | K4: 0.0025 | L4: 0
B5: Carga/Descarga | C5: =F5*E5 -> 0 | D5: =+C5/BASE_EXPORTACION!TC_2023 -> 0 | E5: ='46k'!quintales_2023 -> 233 | F5: 0 | G5: =+F5/BASE_EXPORTACION!TC_2023 -> 0 | H5: =+G5/46 -> 0 | I5: Va en la maquila | L5: =L4*K4 -> 0 | M5: Costo seguro
B6: Costo seguro | C6: =F6 -> 0 | D6: =+C6/BASE_EXPORTACION!TC_2023 -> 0 | E6: ='46k'!quintales_2023 -> 233 | F6: =L5 -> 0 | G6: =+F6/BASE_EXPORTACION!TC_2023 -> 0 | H6: =+G6/46 -> 0
B7: Costo patrulla con custodio | C7: =F7 -> 0 | D7: =+C7/BASE_EXPORTACION!TC_2023 -> 0 | E7: ='46k'!quintales_2023 -> 233 | F7: =L8 -> 0 | G7: =+F7/BASE_EXPORTACION!TC_2023 -> 0 | H7: =+G7/46 -> 0
B8: Sacos | C8: =F8*E8 -> 0 | D8: =+C8/BASE_EXPORTACION!TC_2023 -> 0 | E8: ='46k'!quintales_2023 -> 233 | F8: 0 | G8: =+F8/BASE_EXPORTACION!TC_2023 -> 0 | H8: =+G8/46 -> 0 | L8: 0 | M8: Costo patrulla con custodio
B9: Bolsa | C9: =F9*E9 -> 0 | D9: =+C9/BASE_EXPORTACION!TC_2023 -> 0 | E9: ='46k'!quintales_2023 -> 233 | F9: 0 | G9: =+F9/BASE_EXPORTACION!TC_2023 -> 0 | H9: =+G9/46 -> 0
B10: Comision Compra x qq | C10: =F10*E10 -> 0 | D10: =+C10/BASE_EXPORTACION!TC_2023 -> 0 | E10: ='46k'!quintales_2023 -> 233 | F10: 0 | G10: =+F10/BASE_EXPORTACION!TC_2023 -> 0 | H10: =+G10/46 -> 0 | I10: No hay comprador
B11: COSTO DE ADQUISICION | C11: =SUM(C4:C10) -> 0 | D11: =SUM(D4:D10) -> 0 | E11: ='46k'!quintales_2023 -> 233 | F11: =C11 -> 0 | G11: =+F11/BASE_EXPORTACION!TC_2023 -> 0 | H11: =+G11/46 -> 0

Sheet Anexo2_maquila
B2: ANEXO 2
B3: TRANSFORMACION | C3: Costo total Qtz | D3: Costo total $ | E3: qq | F3: Qtz x qq | G3: US$ | H3: US$ x kg
B4: Maquila | C4: =+E4*F4 -> 39610 | D4: =+C4/BASE_EXPORTACION!TC_2023 -> 5110.9677 | E4: ='46k'!quintales_2023 -> 233 | F4: 170 | G4: =+F4/BASE_EXPORTACION!TC_2023 -> 21.935484 | H4: =+G4/46 -> 0.47685835
B6: TRANSFORMACIÓN | C6: =SUM(C4:C5) -> 39610 | D6: =SUM(D4:D5) -> 5110.9677 | E6: =BASE_EXPORTACION!quintales_2023 -> 500 | F6: =+C6/E6 -> 79.22 | G6: =+F6/BASE_EXPORTACION!TC_2023 -> 10.221935 | H6: =+G6/46 -> 0.22221599

Sheet Anexo3_Cont_20
B2: ANEXO 3
B3: CONTENEDOR DE 20'
B4: FIJOS
B5: GASTOS EXPORTACION | C5: Costo total Qtz | D5: Costo total $ | E5: Kilos | F5: Qtz x Kg | G5: US$
B6: Banco Industrial | C6: =+D6*BASE_EXPORTACION!TC_2023 -> 271.25 | D6: 35 | E6: =IF(BASE_EXPORTACION!N3=0,23000,BASE_EXPORTACION!N3) -> 10000 | F6: =+C6/E6 -> 0.027125 | G6: =+F6/BASE_EXPORTACION!TC_2023 -> 0.0035
B7: Banco BAM SWIFT | C7: =+D7*BASE_EXPORTACION!TC_2023 -> 155 | D7: 20 | E7: =+E6 -> 10000 | F7: =+C7/E7 -> 0.0155 | G7: =+F7/BASE_EXPORTACION!TC_2023 -> 0.002
B8: Certificado de Origen | C8: =+D8*BASE_EXPORTACION!TC_2023 -> 123.3025 | D8: 15.91 | E8: =+E7 -> 10000 | F8: =+C8/E8 -> 0.01233025 | G8: =+F8/BASE_EXPORTACION!TC_2023 -> 0.001591
B9: Fitosanitario | C9: =+D9*BASE_EXPORTACION!TC_2023 -> 49.6775 | D9: 6.41 | E9: =+E8 -> 10000 | F9: =+C9/E9 -> 0.00496775 | G9: =+F9/BASE_EXPORTACION!TC_2023 -> 0.000641
B10: Fumigación | C10: =+D10*BASE_EXPORTACION!TC_2023 -> 1309.285 | D10: 168.94 | E10: =+E9 -> 10000 | F10: =+C10/E10 -> 0.1309285 | G10: =+F10/BASE_EXPORTACION!TC_2023 -> 0.016894
B11: Certificado de Peso y calidad | C11: =+D11*BASE_EXPORTACION!TC_2023 -> 1743.75 | D11: 225 | E11: =+E10 -> 10000 | F11: =+C11/E11 -> 0.174375 | G11: =+F11/BASE_EXPORTACION!TC_2023 -> 0.0225
B12: Agente Aduanal | C12: =+D12*BASE_EXPORTACION!TC_2023 -> 591.8675 | D12: 76.37 | E12: =+E11 -> 10000 | F12: =+C12/E12 -> 0.05918675 | G12: =+F12/BASE_EXPORTACION!TC_2023 -> 0.007637
B13: Envío muestra Pre Embarque DHL | C13: =+D13*BASE_EXPORTACION!TC_2023 -> 1162.5 | D13: 150 | E13: =+E12 -> 10000 | F13: =+C13/E13 -> 0.11625 | G13: =+F13/BASE_EXPORTACION!TC_2023 -> 0.015
B14: Deprex | C14: =+D14*BASE_EXPORTACION!TC_2023 -> 99.975 | D14: 12.9
B15: Logistica | C15: =+D15*BASE_EXPORTACION!TC_2023 -> 3875 | D15: 500 | E15: =+E13 -> 10000 | F15: =+C15/E15 -> 0.3875 | G15: =+F15/BASE_EXPORTACION!TC_2023 -> 0.05
B16: Custodio a puerto | C16: =+D16*BASE_EXPORTACION!TC_2023 -> 643.25 | D16: 83
B17: Flete a Puerto | C17: =+D17*BASE_EXPORTACION!TC_2023 -> 10075 | D17: 1300
B18: MSC Naviera | C18: =+D18*BASE_EXPORTACION!TC_2023 -> 27512.5 | D18: 3550 | E18: =+E32 -> 10000 | F18: =+C18/E18 -> 2.75125 | G18: =+F18/BASE_EXPORTACION!TC_2023 -> 0.355
B19: EXPORTACION | C19: =SUM(C6:C18) -> 47612.357 | D19: =SUM(D6:D18) -> 6143.53 | E19: =+E15 -> 10000 | F19: =+C19/E19 -> 4.7612357 | G19: =+F19/BASE_EXPORTACION!TC_2023 -> 0.614353
B21: VARIABLES POR KG
B22: GASTOS EXPORTACION | C22: Costo total Qtz | D22: Costo total $ | E22: Kilos | F22: Qtz x Kg | G22: US$
B23: 250 Cajas Master MIG | C23: =+E23*F23 -> 5559.075 | D23: 717.3 | E23: =+E6 -> 10000 | F23: =+G23*BASE_EXPORTACION!TC_2023 -> 0.5559075 | G23: =+D23/10000 -> 0.07173 | H23: =+C23/250 -> 22.2363
B24: 2000 Caja Inner MIG | C24: =+E24*F24 -> 8005.0525 | D24: 1032.91 | E24: =+E23 -> 10000 | F24: =+G24*BASE_EXPORTACION!TC_2023 -> 0.80050525 | G24: =+D24/10000 -> 0.103291 | H24: =+C24/2000 -> 4.0025263
B25: Fleje para cajas 40kg | C25: =+E25*F25 -> 266.4627 | D25: 34.382284 | E25: =+E24 -> 10000 | F25: =+G25*BASE_EXPORTACION!TC_2023 -> 0.02664627 | G25: =+D25/10000 -> 0.0034382284 | H25: Ver con la maquila quien paga?
B26: Grapa de Fleje | C26: =+E26*F26 -> 23.183761 | D26: 2.991453 | E26: =+E25 -> 10000 | F26: =+G26*BASE_EXPORTACION!TC_2023 -> 0.0023183761 | G26: =+D26/10000 -> 0.0002991453 | H26: Ver con la maquila quien paga?
B27: Grapa para caja | C27: =+E27*F27 -> 439.58819 | D27: 56.721057 | E27: =+E26 -> 10000 | F27: =+G27*BASE_EXPORTACION!TC_2023 -> 0.043958819 | G27: =+D27/10000 -> 0.0056721057 | H27: Ver con la maquila quien paga?
B28: 2000 Bolsas negras 5gk | C28: =+E28*F28 -> 1262.7075 | D28: 162.93 | E28: =+E27 -> 10000 | F28: =+G28*BASE_EXPORTACION!TC_2023 -> 0.12627075 | G28: =+D28/10000 -> 0.016293 | H28: =+C28/2000 -> 0.63135375
B29: Stickes cliente | C29: =+E29*F29 -> 0 | D29: =763.54*0 -> 0 | E29: =+E28 -> 10000 | F29: =+G29*BASE_EXPORTACION!TC_2023 -> 0 | G29: =+D29/10000 -> 0 | H29: A pedido del cliente
B30: Sellos para Cajas 5kg | C30: =+E30*F30 -> 207.094 | D30: 26.721807 | E30: =+E29 -> 10000 | F30: =+G30*BASE_EXPORTACION!TC_2023 -> 0.0207094 | G30: =+D30/10000 -> 0.0026721807 | H30: =+C30/2000 -> 0.103547
B31: Sellos para Cajas 40kg | C31: =+E31*F31 -> 561.0222 | D31: 72.389961 | E31: =+E30 -> 10000 | F31: =+G31*BASE_EXPORTACION!TC_2023 -> 0.05610222 | G31: =+D31/10000 -> 0.0072389961 | H31: =+C31/250 -> 2.2440888
B32: EXPORTACION | C32: =SUM(C23:C31) -> 16324.186 | D32: =SUM(D23:D31) -> 2106.3466 | E32: =+E31 -> 10000 | F32: =+C32/E32 -> 1.6324186 | G32: =+F32/BASE_EXPORTACION!TC_2023 -> 0.21063466
B34: EXPORTACION | C34: =+C19+C32 -> 63936.543 | D34: =+C34/BASE_EXPORTACION!TC_2023 -> 8249.8766 | E34: =+E18 -> 10000 | F34: =+C34/E34 -> 6.3936543 | G34: =+F34/BASE_EXPORTACION!TC_2023 -> 0.82498766

Sheet Anexo4_Cont_40
B2: ANEXO 4
B3: CONTENEDOR DE 40'
B4: FIJOS
B5: GASTOS EXPORTACION | C5: Costo total Qtz | D5: Costo total $ | E5: Kilos | F5: Qtz x Kg | G5: US$
B6: Banco Industrial | C6: =+D6*BASE_EXPORTACION!TC_2023 -> 271.25 | D6: 35 | E6: =+BASE_EXPORTACION!N4 -> 0 | F6: =IFERROR(C6/E6,0) -> 0 | G6: =+F6/BASE_EXPORTACION!TC_2023 -> 0
B7: Banco BAM SWIFT | C7: =+D7*BASE_EXPORTACION!TC_2023 -> 155 | D7: 20 | E7: =+E6 -> 0 | F7: =IFERROR(C7/E7,0) -> 0 | G7: =+F7/BASE_EXPORTACION!TC_2023 -> 0
B8: Certificado de Origen | C8: =+D8*BASE_EXPORTACION!TC_2023 -> 123.3025 | D8: 15.91 | E8: =+E7 -> 0 | F8: =IFERROR(C8/E8,0) -> 0 | G8: =+F8/BASE_EXPORTACION!TC_2023 -> 0
B9: Fitosanitario | C9: =+D9*BASE_EXPORTACION!TC_2023 -> 49.6775 | D9: 6.41 | E9: =+E8 -> 0 | F9: =IFERROR(C9/E9,0) -> 0 | G9: =+F9/BASE_EXPORTACION!TC_2023 -> 0
B10: Fumigación | C10: =+D10*BASE_EXPORTACION!TC_2023 -> 1309.285 | D10: 168.94 | E10: =+E9 -> 0 | F10: =IFERROR(C10/E10,0) -> 0 | G10: =+F10/BASE_EXPORTACION!TC_2023 -> 0
B11: Certificado de Peso y calidad | C11: =+D11*BASE_EXPORTACION!TC_2023 -> 1743.75 | D11: 225 | E11: =+E10 -> 0 | F11: =IFERROR(C11/E11,0) -> 0 | G11: =+F11/BASE_EXPORTACION!TC_2023 -> 0
B12: Agente Aduanal | C12: =+D12*BASE_EXPORTACION!TC_2023 -> 591.8675 | D12: 76.37 | E12: =+E11 -> 0 | F12: =IFERROR(C12/E12,0) -> 0 | G12: =+F12/BASE_EXPORTACION!TC_2023 -> 0
B13: Envío muestra Pre Embarque DHL | C13: =+D13*BASE_EXPORTACION!TC_2023 -> 1162.5 | D13: 150 | E13: =+E12 -> 0 | F13: =IFERROR(C13/E13,0) -> 0 | G13: =+F13/BASE_EXPORTACION!TC_2023 -> 0
B14: Logistica | C14: =+D14*BASE_EXPORTACION!TC_2023 -> 3875 | D14: 500 | E14: =+E13 -> 0 | F14: =IFERROR(C14/E14,0) -> 0 | G14: =+F14/BASE_EXPORTACION!TC_2023 -> 0
B15: MSC Naviera | C15: =+D15*BASE_EXPORTACION!TC_2023 -> 38258.043 | D15: =5677/23000*20000 -> 4936.5217 | E15: =+E21 -> 0 | F15: =IFERROR(C15/E15,0) -> 0 | G15: =+F15/BASE_EXPORTACION!TC_2023 -> 0
B16: EXPORTACION | C16: =SUM(C2:C15) -> 47539.676 | D16: =SUM(D2:D15) -> 6134.1517 | E16: =+E14 -> 0 | F16: =IFERROR(C16/E16,0) -> 0 | G16: =+F16/BASE_EXPORTACION!TC_2023 -> 0
B18: VARIABLES POR KG
B19: GASTOS EXPORTACION | C19: Costo total Qtz | D19: Costo total $ | E19: Kilos | F19: Qtz x Kg | G19: US$
B20: 500 Cajas Master MIG | C20: =+E20*F20 -> 0 | D20: =717.3*2 -> 1434.6 | E20: =+E6 -> 0 | F20: =G20*BASE_EXPORTACION!TC_2023 -> 0.48339783 | G20: =+D20/23000 -> 0.062373913 | H20: =+C20/250 -> 0
B21: 4000 Caja Inner MIG | C21: =+E21*F21 -> 0 | D21: =1032.91*2 -> 2065.82 | E21: =+E20 -> 0 | F21: =G21*BASE_EXPORTACION!TC_2023 -> 0.69609152 | G21: =+D21/23000 -> 0.089818261 | H21: =+C21/2000 -> 0
B22: Fleje para cajas 40kg | C22: =+E22*F22 -> 0 | D22: =79.0792540792541/23000*20000 -> 68.764569 | E22: =+E21 -> 0 | F22: =G22*BASE_EXPORTACION!TC_2023 -> 0.02317067 | G22: =+D22/23000 -> 0.0029897639 | H22: Ver con la maquila quien paga?
B23: Grapa de Fleje | C23: =+E23*F23 -> 0 | D23: =6.88034188034188/23000*20000 -> 5.982906 | E23: =+E22 -> 0 | F23: =G23*BASE_EXPORTACION!TC_2023 -> 0.0020159792 | G23: =+D23/23000 -> 0.00026012635 | H23: Ver con la maquila quien paga?
B24: Grapa para caja | C24: =+E24*F24 -> 0 | D24: =130.45843045843/23000*20000 -> 113.44211 | E24: =+E23 -> 0 | F24: =G24*BASE_EXPORTACION!TC_2023 -> 0.03822506 | G24: =+D24/23000 -> 0.0049322658 | H24: Ver con la maquila quien paga?
B25: 4600 Bolsas negras 5kg | C25: =+E25*F25 -> 0 | D25: =(162.93/2000*4600)/23000*20000 -> 325.86 | E25: =+E24 -> 0 | F25: =G25*BASE_EXPORTACION!TC_2023 -> 0.10980065 | G25: =+D25/23000 -> 0.014167826 | H25: =+C25/2000 -> 0
B26: Stickes cliente | C26: =+E26*F26 -> 0 | D26: =763.537479909915/10000*20000*0 -> 0 | E26: =+E25 -> 0 | F26: =G26*BASE_EXPORTACION!TC_2023 -> 0 | G26: =+D26/23000 -> 0 | H26: A pedido del cliente
B27: Sellos para Cajas 5kg | C27: =+E27*F27 -> 0 | D27: =26.7218069031335/10000*20000 -> 53.443614 | E27: =+E26 -> 0 | F27: =G27*BASE_EXPORTACION!TC_2023 -> 0.018008174 | G27: =+D27/23000 -> 0.0023236354 | H27: =+C27/2000 -> 0
B28: Sellos para Cajas 40kg | C28: =+E28*F28 -> 0 | D28: =72.3899609094211/10000*20000 -> 144.77992 | E28: =+E27 -> 0 | F28: =G28*BASE_EXPORTACION!TC_2023 -> 0.048784539 | G28: =+D28/23000 -> 0.0062947792 | H28: =+C28/250 -> 0
B29: EXPORTACION | C29: =SUM(C20:C28) -> 0 | D29: =SUM(D20:D28) -> 4212.6931 | E29: =+E28 -> 0 | F29: =+C29/E29 -> #DIV/0! | G29: =IFERROR(F29/BASE_EXPORTACION!TC_2023,0) -> 0
B31: EXPORTACION | C31: =+C16+C29 -> 47539.676 | D31: =+C31/BASE_EXPORTACION!TC_2023 -> 6134.1517 | E31: =+E15 -> 0 | F31: =+C31/E31 -> #DIV/0! | G31: =+F31/BASE_EXPORTACION!TC_2023 -> #DIV/0!

Sheet Anexo5_Gtos_variables
B1: PRODUCTO | C1: APLICA | D1: BASE DE FACTURA
B2: 1RAS | C2: 1 | D2: =+BASE_EXPORTACION!I11*C2 -> 391586.76 | G2: 1 = APLICA GASTO VARIABLE
B3: 2DAS | C3: 1 | D3: =+BASE_EXPORTACION!I14*C3 -> 367387.58 | G3: 0 = NO APLICA
B4: 3RAS | C4: 1 | D4: =+BASE_EXPORTACION!I20*C4 -> 0
B5: ANEXO 5
B6: VARIABLES S/FACTURA | C6: % | D6: MONTO FACT $ | E6: COSTO VARIABLE
B7: Seguro de Carga 0.25% | C7: 0.0025 | D7: ='46k'!I21 -> 340094.2 | E7: =+C7*D7 -> 850.23549
B8: Banco BAM 0.15% | C8: 0.0015 | D8: =+D7 -> 340094.2 | E8: =+C8*D8 -> 510.1413
B9: BAM Gtos. De Cobranza 0.5% | C9: 0.005 | D9: =+D8 -> 340094.2 | E9: =+C9*D9 -> 1700.471
B10: Comisión Venta 1% | C10: 0 | D10: =+D9 -> 340094.2 | E10: =+C10*D10 -> 0
B11: Agente 2% | C11: 0.02 | D11: =+D10 -> 340094.2 | E11: =+C11*D11 -> 6801.884
B12: COSTA VARIABLE | C12: =SUM(C7:C11) -> 0.029 | D12: =+D11 -> 340094.2 | E12: =SUM(E7:E11) -> 9862.7317

Sheet Anexo6_Gastos Fijos
B2: HONORARIOS:
B3: PUESTO | C3: NOMBRE | D3: MESES | E3: US$ x Mes | F3: TOTAL AÑO | G3: TC | H3: QTZ x Mes | I3: QTZ AÑO
B4: Gerente General | C4: Lic. José Herrera | D4: 6 | E4: 0 | F4: =+'Anexo6_Gastos Fijos'!$E$4*'Anexo6_Gastos Fijos'!$D$4 -> 0 | G4: =BASE_EXPORTACION!TC_2023 -> 7.75 | H4: =+'Anexo6_Gastos Fijos'!$E$4*'Anexo6_Gastos Fijos'!$G$4 -> 0 | I4: =+'Anexo6_Gastos Fijos'!$F$4*'Anexo6_Gastos Fijos'!$G$4 -> 0
B5: Control de calidad | C5: Gustavo | D5: 6 | E5: 0 | F5: =+'Anexo6_Gastos Fijos'!$E$5*'Anexo6_Gastos Fijos'!$D$5 -> 0 | G5: =BASE_EXPORTACION!TC_2023 -> 7.75 | H5: =+'Anexo6_Gastos Fijos'!$E$5*'Anexo6_Gastos Fijos'!$G$5 -> 0 | I5: =+'Anexo6_Gastos Fijos'!$F$5*'Anexo6_Gastos Fijos'!$G$5 -> 0
B6: Finanzas | C6: TCG Finanzas | D6: 12 | E6: 500 | F6: =+'Anexo6_Gastos Fijos'!$E$6*'Anexo6_Gastos Fijos'!$D$6 -> 6000 | G6: =BASE_EXPORTACION!TC_2023 -> 7.75 | H6: =+'Anexo6_Gastos Fijos'!$E$6*'Anexo6_Gastos Fijos'!$G$6 -> 3875 | I6: =+'Anexo6_Gastos Fijos'!$F$6*'Anexo6_Gastos Fijos'!$G$6 -> 46500 | K6: Fee mensual por contabilidad y analisis financieros
B7: Auditoria Externa | C7: Grant Tourton | D7: 1 | E7: 0 | F7: =+'Anexo6_Gastos Fijos'!$E$7*'Anexo6_Gastos Fijos'!$D$7 -> 0 | G7: =BASE_EXPORTACION!TC_2023 -> 7.75 | H7: =+'Anexo6_Gastos Fijos'!$E$7*'Anexo6_Gastos Fijos'!$G$7 -> 0 | I7: =+'Anexo6_Gastos Fijos'!$F$7*'Anexo6_Gastos Fijos'!$G$7 -> 0
B8: Total | E8: =SUBTOTAL(109,E4:E7) -> 500 | F8: =SUBTOTAL(109,F4:F7) -> 6000 | H8: =SUBTOTAL(109,H4:H7) -> 3875 | I8: =SUBTOTAL(109,I4:I7) -> 46500
